Workbook

Sheet README
B1: Open Budget Survey (OBS) 2025 – Public Data Statfile (Launch 2 Public Release)
B3: Structure of the workbook
B5: Data_Dictionary: Definitions, types, value coding, and notes for all variables
B6: Question_Map: Mapping of survey questions to their possible responses
B7: OBS_Data_2006-2025: Main dataset containing country identifiers, composite scores, and indicator variables
B8: Summary_3_Pillars: High-level pillar scores for OBS 2025 and OBS 2023 where applicable
B9: Scores + Letters: Expanded view with numeric scores and selected categorical/letter-coded fields used in reporting (Data available for OBS 2017-OBS 2025)
B10: Metadata_UI: Supporting metadata with individual country results including source and comment fields
B11: General_Questions_UI: Unscored general questions for individual countries
B12: Indicator_Change: Change in score for each indicator from OBS 2023 to OBS 2025
B14: About this dataset
B15: The Open Budget Survey (OBS) is an independent, comparative assessment of national budget processes. It evaluates three core dimensions of budget accountability: budget transparency (Open Budget Index – OBI), public participation, and oversight (Legislative + SAI).
... B52: File prepared for public release on 2026-04-14. Release: Launch 2 of 4 Countries included in this file: 31 of 83 OBS year: 2025

Sheet Data_Dictionary
B1: Data Dictionary — This sheet describes the variables included in the OBS dataset, including variable names/patterns, definitions, data types, value coding, and methodological notes. Users should review the README tab for important comparability notes and methodological caveats.
B3: Quick reference: common variable prefixes
B4: • q* — Scored OBS survey indicators
B5: • gq* — General questions (unscored; contextual use)
B6: • obi / *_obi — Transparency and oversight indices and related components
B7: • round* — Round-level composite values
B8: • grade_* / *_cat* — Categorical groupings used in reporting
B10: OBS_Data_2006-2025_Codebook
B12: Variable / Pattern | C12: Description | D12: Type | E12: Values / Coding | F12: Notes
B13: year | C13: OBS survey round year | D13: Number | E13: 2006 - 2025 (in this launch) | F13: Data are available from 2006 onward. If a country does not appear in a given year, it means the country was not included in the survey that year.
B14: region | C14: Broad regional classification | D14: Text
B15: rank | C15: Country rank in the Open Budget Index (OBI) | D15: Number | F15: Rankings are provisional in partial releases. Final rankings will be available only after all participating countries are published.
B16: obi | C16: Open Budget Index (OBI) transparency score | D16: Number (0–100) | E16: Average of q1–q102 and timeliness variables (t3pbs, t3ebp, t3eb, t3iyr, t3myr, t3yer, t3ar) | F16: Calculated as an unweighted average. roundobi is the OBI score rounded to the nearest whole number.
B17: obi_cat | C17: Category based on rounded transparency (OBI) score | D17: Categorical | E17: Scant or None; Minimal; Limited; Substantial; Extensive | F17: Categories are based on the rounded OBI score: • 0–20: Scant or no information • 21–40: Minimal information • 41–60: Limited information • 61–80: Substantial information • 81–100: Extensive information
B18: obi_cat2 | C18: Simplified transparency category based on rounded OBI score | D18: Categorical | E18: Low; Limited; Sufficient | F18: Categories are based on the rounded OBI score: • 0-40: Low • 41-60: Limited • 61-100: Sufficient
B19: obi_cat3 | C19: Binary transparency sufficiency category | D19: Categorical | E19: Insufficient; Sufficient | F19: A score of 61 or higher for the OBI is considered sufficient.
B20: obi_cat4 | C20: Quintile classification of rounded OBI score | D20: Categorical | E20: Bottom Quintile; 2nd Quintile; Middle Quintile; 4th Quintile; Top Quintile | F20: Categories are based on the rounded OBI score: • 0-20: Bottom Quintile • 21-40: 2nd Quintile • 41-60: Middle Quintile • 61-80: 4th Quintile • 81-100: Top Quintile
B21: oversight_obi | C21: Overall oversight score (legislature + SAI) | D21: Number (0–100) | E21: Unweighted average of q107–q124 | F21: Do not compare oversight scores prior to 2017, as the questions and structure changed in earlier rounds. Roundoversight_obi is the rounded value.
B22: leg_obi | C22: Legislature oversight sub-score | D22: Number (0–100) | E22: Unweighted average of q107-q118 | F22: Do not compare prior to 2017. Roundleg_obi is the rounded value.
B23: sai_obi | C23: Supreme Audit Institution (SAI) oversight sub-score | D23: Number (0–100) | E23: Unweighted average of q119-q124 | F23: Do not compare prior to 2017. Roundsai_obi is the rounded value.
B24: ifi_obi | C24: Independent Fiscal Institution (IFI) sub-score | D24: Number (0–100) | E24: Unweighted average of q103-q106 | F24: Exploratory indicator assessing Independent Fiscal Institutions (IFI). Not included in composite indices. roundifi_obi is the rounded value.
B25: grade_oversight, grade_leg, grade_sai, grade_ifi | C25: Category based on rounded oversight sub-scores | D25: Categorical | E25: Weak; Limited; Adequate | F25: • 0-40: Weak • 41-60: Limited • 61-100: Adequate
B26: pub_eng | C26: Public participation score | D26: Number (0–100) | E26: Unweighted average of q125-q142 | F26: Do not compare participation scores prior to 2017 due to questionnaire changes. roundpub_eng is the rounded value.
B27: grade_pub_eng | C27: Public participation category based on rounded score | D27: Categorical | E27: Few or no opportunities; Limited opportunities; Adequate opportunities | F27: • 0-40: Few or no opportunities • 41-60: Limited opportunities • 61-100: Adequate opportunities
... B38: Q1LETTER-Q142LETTER | C38: Letter responses corresponding to indicator scores (available in Scores + Letters tab) | D38: Text | E38: a/b/c/d/e | F38: Data for letters is only present since 2017 OBS as questions as the structure of the questions changed prior to that. Most indicators will have five response options (A through E), while some will have three (A through C) and depending on the option have different scoring conversions. Five-option indicators: • a = 100 • b = 67 • c = 33, • d = 0 • e = Not applicable (and thus not counted) Three-option indicators: • a = 100 • B = 0 • C = Not applicable (and thus not counted)
B41: Metadata_UI_Codebook
B43: Variable / Pattern | C43: Description | D43: Type | E43: Values / Coding | F43: Notes
B44: Q | C44: Indicator identifier | D44: Text | E44: q1–q142; t3pbs, t3ebp, t3eb, t3iyr, t3myr, t3yer, t3ar | F44: Provides information on scored OBS indicators and selected unscored indicators related to independent fiscal institutions.
B45: Group | C45: Composite index/pillar to which the indicator contributes | D45: Category | E45: The Open Budget Index, Unscored (IFI), Role and Effectiveness of Oversight Institutions, Public Participation in the Budget Process | F45: Indicator grouping: • Open Budget Index (Transparency): q1–q102 and timeliness variables ( t3pbs, t3ebp, t3eb, t3iyr, t3myr, t3yer, t3ar) • Unscored (IFI): q103–q106 • Oversight: q107–q124 • Public Participation: q125–q142
B46: Doc | C46: Budget document assessed by the indicator | D46: Category | E46: PBS, EBP, EB, CB, IYR, MYR, YER, AR | F46: Applies only to Open Budget Index (OBI) indicators (q1–q102 and timeliness variables). Document coverage: • PBS: t3pbs and q54–q58 • EBP: t3ebp and q1–q53 • EB: t3eb and q59–q63 • CB: q64–q67 • IYR: t3iyr and q68–q75 • MYR: t3myr and q76–q83 • YER: t3yer and q84–q96 • AR: t3ar and q97–q102
B47: Stage | C47: Stage of the budget cycle assessed by the indicator | D47: Category | E47: All Stages, Formulation, Approval, Execution, Oversight | F47: Stage classification: • All Stages: q64–q67, q131, q135 • Formulation: t3pbs, t3ebp, q1–q58, q107, q125–q127, q132, q134 • Approval: t3eb, q59–q63, q108–q113, q136–q138 • Execution: t3iyr, t3myr, t3yer, q68–q96, q114–q117, q128–q130, q133 • Oversight: t3ar, q97–q102, q103–q106 (IFI), q118–q124, q139–q142c
B48: Topic | C48: Thematic classification of the indicator | D48: Category | E48: Timeliness, Expenditure, Revenue, Debt, Macroeconomic, Policy & Performance, Fiscal Risk, Timetable, Citizens Version, Audit, SAI, Legislature, IFI, Executive, Line Ministries | F48: Topic mapping: • Timeliness: t3pbs, t3ebp, t3eb, t3iyr, t3myr, t3yer, t3ar • Expenditure: q1–q8, q19–q24, q55, q58–q60, q68–q70, q77–q79, q84–q86 • Revenue: q9–q12, q25–q30, q56, q61–q62, q71–q73, q80–q82, q87–q89 • Debt: q13–q14, q31–q32, q57, q63, q74–q75, q83, q90 • Macroeconomic: q15–q16, q54, q76, q91 • Policy & Performance: q17–q18, q36, q47–q52, q92–q94 • Fiscal Risk: q33–q35, q37–q46, q95–q96 • Timetable: q53 • Citizens Version: q64–q67 • Audit: q97–q102 • SAI: q119–q124, q140–q142 • Legislature: q107–q118, q136–q139 • IFI: q103–q106 • Executive: q125–q134 • Line Ministries: q135
B49: Question | C49: Full text of the OBS questionnaire | D49: Text | F49: Multiple-choice response options are not included here. See the question mapping tab for response options.
B50: Country | C50: Country name | D50: Text
B51: ISO | C51: Alpha-3 ISO country code | D51: Text | E51: e.g., ALB, BIH, XKX, MNE, MKD, SRB, TUR
B52: Year | C52: OBS survey year | D52: Number | E52: 2025 (in this launch) | F52: Currently includes only the 2025 round.
B53: Score | C53: Numerical score (0–100) assigned to the indicator | D53: Number (0–100) | F53: Derived from the selected multiple-choice response.
B54: Response | C54: Selected multiple-choice answer | D54: Text | F54: Recorded exactly as selected in the survey instrument.
B55: Source | C55: Source(s) supporting the assigned score | D55: Text | F55: Typically includes URLs, official documents, and page references.
B56: Comment | C56: Researcher’s explanation and evidence supporting the assigned score | D56: Text | F56: The untransformed comment from the researcher prior to external review used to support the score.
...

Sheet Question_Map
B1: To users as you will notice most indicators will have five response options (A through E), while some will have three (A through C). > ABC_SET = q2-q5, q11, q21, q25, q27, q28, q34, q58, q61, q70, q71, q73, q81, q88, q96, q100, q119, q120, q126, q129, q134, q140, q142 > All else are the five response options (A through E)
B4: Indicator | C4: Topic | D4: Question | E4: A | F4: B | G4: C | H4: D | I4: E
B5: PBS-2 | C5: Transparency - Pre-Budget Statement | D5: When is the Pre-Budget Statement made available to the public? | E5: At least four months in advance of the budget year, and at least one month before the executive’s budget proposal is introduced in the legislature | F5: At least two months, but less than four months, in advance of the budget year, and at least one month before the executive’s budget proposal is introduced in the legislature | G5: Less than two months in advance of the budget year, but at least one month before the executive’s budget proposal is introduced in the legislature | H5: Does not release to the public, or is released less than one month before the executive’s budget proposal is introduced to the legislature
B6: EBP-2 | C6: Transparency - Executive's Budget Proposal | D6: When is the Executive Budget Proposal made available to the public? | E6: At least three months in advance of the budget year, and in advance of the budget being approved by the legislature | F6: At least two months, but less than three months, in advance of the budget year, and in advance of the budget being approved by the legislature | G6: Less than two months in advance of the budget year, but at least in advance of the budget being approved by the legislature | H6: Does not release to the public, or is released after the budget has been approved by the legislature
B7: EB-2 | C7: Transparency - Enacted Budget | D7: When is the Enacted Budget made available to the public? | E7: Two weeks or less after the budget has been enacted | F7: Between two weeks and six weeks after the budget has been enacted | G7: More than six weeks, but less than three months, after the budget has been enacted | H7: Does not release to the public, or is released more than three months after the budget has been enacted
B8: IYRs-2 | C8: Transparency - In-Year Reports | D8: When are In-Year Reports made available to the public? | E8: At least every month, and within one month of the period covered | F8: At least every quarter, and within three months of the period covered | G8: At least semi-annually, and within three months of the period covered | H8: Does not release to the public
B9: MYR-2 | C9: Transparency - Mid-Year Review | D9: How long after the mid-point in the fiscal year (i.e., six months into the fiscal year) is the Mid-Year Review made available to the public? | E9: Six weeks or less after the mid-point | F9: Nine weeks or less, but more than six weeks, after the mid-point | G9: More than nine weeks, but less than three months, after the mid-point | H9: Does not release to the public, or is released more than three months after the mid-point
B10: YER-2 | C10: Transparency - Year-End Report | D10: How long after the end of the budget year is the Year-End Report made available to the public? | E10: Six months or less after the end of the budget year | F10: Nine months or less, but more than six months, after the end of the budget year | G10: More than nine months, but within 12 months, after the end of the budget year | H10: Does not release to the public, or is released more than 12 months after the end of the budget year
B11: AR-2 | C11: Transparency - Audit Report | D11: How long after the end of the fiscal year are the final annual expenditures of national departments audited and released (except for secret programs)? | E11: Six months or less after the end of the budget year | F11: 12 months or less, but more than six months, after the end of the budget year | G11: More than 12 months, but within 18 months, after the end of the budget year | H11: Does not release to the public, or is released more than 18 months after the end of the budget year
B12: 1 | C12: Transparency - Executive's Budget Proposal | D12: Does the Executive’s Budget Proposal or any supporting budget documentation present expenditures for the budget year that are classified by administrative unit (that is, by ministry, department, or agency)? | E12: Yes, administrative units accounting for all expenditures are presented. | F12: Yes, administrative units accounting for at least two-thirds of, but not all, expenditures are presented. | G12: Yes, administrative units accounting for less than two-thirds of expenditures are presented. | H12: No, expenditures are not presented by administrative unit. | I12: Not applicable/other (please comment).
B13: 2 | C13: Transparency - Executive's Budget Proposal | D13: Does the Executive’s Budget Proposal or any supporting budget documentation present expenditures for the budget year by functional classification? | E13: Yes, expenditures are presented by functional classification. | F13: No, expenditures are not presented by functional classification. | G13: Not applicable/other (please comment).
B14: 3 | C14: Transparency - Executive's Budget Proposal | D14: If the Executive’s Budget Proposal or any supporting budget documentation presents expenditures for the budget year by functional classification, is the functional classification compatible with international standards? | E14: Yes, the functional classification is compatible with international standards. | F14: No, the functional classification is not compatible with international standards, or expenditures are not presented by functional classification. | G14: Not applicable/other (please comment).
B15: 4 | C15: Transparency - Executive's Budget Proposal | D15: Does the Executive’s Budget Proposal or any supporting budget documentation present expenditures for the budget year by economic classification? | E15: Yes, expenditures are presented by economic classification. | F15: No, expenditures are not presented by economic classification. | G15: Not applicable/other (please comment).
B16: 5 | C16: Transparency - Executive's Budget Proposal | D16: If the Executive’s Budget Proposal or any supporting budget documentation presents expenditures for the budget year by economic classification, is the economic classification compatible with international standards? | E16: Yes, the economic classification is compatible with international standards. | F16: No, the economic classification is not compatible with international standards, or expenditures are not presented by economic classification. | G16: Not applicable/other (please comment).
B17: 6 | C17: Transparency - Executive's Budget Proposal | D17: Does the Executive’s Budget Proposal or any supporting budget documentation present expenditures for individual programs for the budget year? | E17: Yes, programs accounting for all expenditures are presented. | F17: Yes, programs accounting for at least two-thirds of, but not all, expenditures are presented. | G17: Yes, programs accounting for less than two-thirds of expenditures are presented. | H17: No, expenditures are not presented by program. | I17: Not applicable/other (please comment).
B18: 7 | C18: Transparency - Executive's Budget Proposal | D18: Does the Executive’s Budget Proposal or any supporting budget documentation present expenditure estimates for a multi-year period (at least two-years beyond the budget year) by any of the three expenditure classifications (by administrative, economic, or functional classification)? | E18: Yes, multi-year expenditure estimates are presented by all three expenditure classifications (by administrative, economic, and functional classification). | F18: Yes, multi-year expenditure estimates are presented by two of the three expenditure classifications. | G18: Yes, multi-year expenditure estimates are presented by only one of the three expenditure classifications. | H18: No, multi-year expenditure estimates are not presented by any expenditure classification. | I18: Not applicable/other (please comment).
B19: 8 | C19: Transparency - Executive's Budget Proposal | D19: Does the Executive’s Budget Proposal or any supporting budget documentation present expenditure estimates for a multi-year period (at least two-years beyond the budget year) by program? | E19: Yes, multi-year estimates for programs accounting for all expenditures are presented. | F19: Yes, multi-year estimates for programs accounting for at least two-thirds of, but not all, expenditures are presented. | G19: Yes, multi-year estimates for programs accounting for less than two-thirds of expenditures are presented. | H19: No, multi-year estimates for programs are not presented. | I19: Not applicable/other (please comment).
B20: 9 | C20: Transparency - Executive's Budget Proposal | D20: Does the Executive’s Budget Proposal or any supporting budget documentation present the individual sources of tax revenue (such as income tax or VAT) for the budget year? | E20: Yes, individual sources of tax revenue accounting for all tax revenue are presented. | F20: Yes, individual sources of tax revenue accounting for at least two-thirds of, but not all, tax revenues are presented. | G20: Yes, individual sources of tax revenue accounting for less than two-thirds of all tax revenues are presented. | H20: No, individual sources of tax revenue are not presented. | I20: Not applicable/other (please comment).
B21: 10 | C21: Transparency - Executive's Budget Proposal | D21: Does the Executive’s Budget Proposal or any supporting budget documentation present the individual sources of non-tax revenue (such as grants, property income, and sales of government-produced goods and services) for the budget year? | E21: Yes, individual sources of non-tax revenue accounting for all non-tax revenue are presented. | F21: Yes, individual sources of non-tax revenue accounting for at least two-thirds of, but not all, non-tax revenues are presented. | G21: Yes, individual sources of non-tax revenue accounting for less than two-thirds of all non-tax revenues are presented. | H21: No, individual sources of non-tax revenue are not presented. | I21: Not applicable/other (please comment).
B22: 11 | C22: Transparency - Executive's Budget Proposal | D22: Does the Executive’s Budget Proposal or any supporting budget documentation present revenue estimates by category (such as tax and non-tax) for a multi-year period (at least two-years beyond the budget year)? | E22: Yes, multi-year estimates of revenue are presented by category. | F22: No, multi-year estimates of revenue are not presented by category. | G22: Not applicable/other (please comment).
B23: 12 | C23: Transparency - Executive's Budget Proposal | D23: Does the Executive’s Budget Proposal or any supporting budget documentation present estimates for individual sources of revenue presented for a multi-year period (at least two-years beyond the budget year)? | E23: Yes, multi-year estimates for individual sources of revenue accounting for all revenue are presented. | F23: Yes, multi-year estimates for individual sources of revenue accounting for at least two-thirds of, but not all, revenue are presented. | G23: Yes, multi-year estimates for individual sources of revenue accounting for less than two-thirds of revenue are presented. | H23: No, multi-year estimates for individual sources of revenue are not presented. | I23: Not applicable/other (please comment).
B24: 13 | C24: Transparency - Executive's Budget Proposal | D24: Does the Executive’s Budget Proposal or any supporting budget documentation present three estimates related to government borrowing and debt: the amount of net new borrowing required during the budget year; the total debt outstanding at the end of the budget year; and interest payments on the debt for the budget year? | E24: Yes, all three estimates related to government borrowing and debt are presented. | F24: Yes, two of the three estimates related to government borrowing and debt are presented. | G24: Yes, one of the three estimates related to government borrowing and debt are presented. | H24: No, none of the three estimates related to government borrowing and debt are not presented. | I24: Not applicable/other (please comment).
B25: 14 | C25: Transparency - Executive's Budget Proposal | D25: Does the Executive’s Budget Proposal or any supporting budget documentation present information related to the composition of the total debt outstanding at the end of the budget year? (The core information must include interest rates on the debt instruments; maturity profile of the debt; and whether it is domestic or external debt.) | E25: Yes, information beyond the core elements is presented for the composition of the total debt outstanding. | F25: Yes, the core information is presented for the composition of the total debt outstanding. | G25: Yes, information is presented, but it excludes some core elements. | H25: No, information related to composition of total debt outstanding is not presented. | I25: Not applicable/other (please comment).
B26: 15 | C26: Transparency - Executive's Budget Proposal | D26: Does the Executive’s Budget Proposal or any supporting budget documentation present information on the macroeconomic forecast upon which the budget projections are based? (The core information must include a discussion of the economic outlook with estimates of nominal GDP level, inflation rate, real GDP growth, and interest rates.) | E26: Yes, information beyond the core elements is presented for the macroeconomic forecast. | F26: Yes, the core information is presented for the macroeconomic forecast. | G26: Yes, information is presented, but it excludes some core elements. | H26: No, information related to the macroeconomic forecast is not presented. | I26: Not applicable/other (please comment).
B27: 16 | C27: Transparency - Executive's Budget Proposal | D27: Does the Executive’s Budget Proposal or any supporting budget documentation show the impact of different macroeconomic assumptions (i.e., sensitivity analysis) on the budget? (The core information must include estimates of the impact on expenditures, revenue, and debt of different assumptions for the inflation rate, real GDP growth, and interest rates.) | E27: Yes, information beyond the core elements is presented to show the impact of different macroeconomic assumptions on the budget. | F27: Yes, the core information is presented to show the impact of different macroeconomic assumptions on the budget. | G27: Yes, information is presented, but it excludes some core elements. | H27: No, information related to different macroeconomic assumptions is not presented. | I27: Not applicable/other (please comment).
B28: 17 | C28: Transparency - Executive's Budget Proposal | D28: Does the Executive’s Budget Proposal or any supporting budget documentation present information for at least the budget year that shows how new policy proposals, as distinct from existing policies, affect expenditures? | E28: Yes, estimates that show how all new policy proposals affect expenditures are presented, along with a narrative discussion. | F28: Yes, estimates that show how all new policy proposals affect expenditures are presented, but a narrative discussion is not included. | G28: Yes, information that shows how some but not all new policy proposals affect expenditure is presented. | H28: No, information that shows how new policy proposals affect expenditure is not presented. | I28: Not applicable/other (please comment).
B29: 18 | C29: Transparency - Executive's Budget Proposal | D29: Does the Executive’s Budget Proposal or any supporting budget documentation present information for at least the budget year that shows how new policy proposals, as distinct from existing policies, affect revenues? | E29: Yes, estimates that show how all new policy proposals affect revenues are presented, along with a narrative discussion. | F29: Yes, estimates that show how all new policy proposals affect revenues are presented, but a narrative discussion is not included. | G29: Yes, information that shows how some but not all new policy proposals affect revenues are presented. | H29: No, information that shows how new policy proposals affect revenues is not presented. | I29: Not applicable/other (please comment).
B30: 19 | C30: Transparency - Executive's Budget Proposal | D30: Does the Executive’s Budget Proposal or any supporting budget documentation present expenditures for the year preceding the budget year (BY-1) by any of the three expenditure classifications (by administrative, economic, or functional classification)? | E30: Yes, expenditure estimates for BY-1 are presented by all three expenditure classifications (by administrative, economic, and functional classification). | F30: Yes, expenditure estimates for BY-1 are presented by two of the three expenditure classifications. | G30: Yes, expenditure estimates for BY-1 are presented by only one of the three expenditure classifications. | H30: No, expenditure estimates for BY-1 are not presented by any expenditure classification. | I30: Not applicable/other (please comment).
B31: 20 | C31: Transparency - Executive's Budget Proposal | D31: Does the Executive’s Budget Proposal or any supporting budget documentation present expenditures for individual programs for the year preceding the budget year (BY-1)? | E31: Yes, programs accounting for all expenditures are presented for BY-1. | F31: Yes, programs accounting for at least two-thirds of, but not all, expenditures are presented for BY-1. | G31: Yes, programs accounting for less than two-thirds of expenditures are presented for BY-1. | H31: No, expenditures are not presented by program for BY-1. | I31: Not applicable/other (please comment).
B32: 21 | C32: Transparency - Executive's Budget Proposal | D32: In the Executive’s Budget Proposal or any supporting budget documentation, have expenditure estimates of the year prior to the budget year (BY-1) been updated from the original enacted levels to reflect actual expenditures? | E32: Yes, expenditure estimates for BY-1 have been updated from the original enacted levels. | F32: No, expenditure estimates for BY-1 have not been updated from the original enacted levels. | G32: Not applicable/other (please comment).
B33: 22 | C33: Transparency - Executive's Budget Proposal | D33: Does the Executive’s Budget Proposal or any supporting budget documentation present estimates of expenditure for more than one year prior to the budget year (that is, BY-2 and prior years) by any of the three expenditure classifications (by administrative, economic, or functional classification)? | E33: Yes, expenditure estimates for BY-2 and prior years are presented by all three expenditure classifications (by administrative, economic, and functional classification). | F33: Yes, expenditure estimates for BY-2 and prior years are presented by two of the three expenditure classifications. | G33: Yes, expenditure estimates for BY-2 and prior years are presented by only one of the three expenditure classifications. | H33: No, expenditure estimates for BY-2 and prior years are not presented by any expenditure classification. | I33: Not applicable/other (please comment).
B34: 23 | C34: Transparency - Executive's Budget Proposal | D34: Does the Executive’s Budget Proposal or any supporting budget documentation present expenditures for individual programs for more than one year preceding the budget year (that is, BY-2 and prior years)? | E34: Yes, programs accounting for all expenditures are presented for BY-2 and prior years. | F34: Yes, programs accounting for at least two-thirds of, but not all, expenditures are presented for BY-2 and prior years. | G34: Yes, programs accounting for less than two-thirds of expenditures are presented for BY-2 and prior years. | H34: No, expenditures are not presented by program for BY-2 and prior years. | I34: Not applicable/other (please comment).
B35: 24 | C35: Transparency - Executive's Budget Proposal | D35: In the Executive’s Budget Proposal or any supporting budget documentation, what is the most recent year presented for which all expenditures reflect actual outcomes? | E35: Two years prior to the budget year (BY-2). | F35: Three years prior to the budget year (BY-3). | G35: Before BY-3. | H35: No actual data for all expenditures are presented in the budget or supporting budget documentation. | I35: Not applicable/other (please comment).
B36: 25 | C36: Transparency - Executive's Budget Proposal | D36: Does the Executive’s Budget Proposal or any supporting budget documentation present revenue by category (such as tax and non-tax) for the year preceding the budget year (BY-1)? | E36: Yes, revenue estimates for BY-1 are presented by category. | F36: No, revenue estimates for BY-1 are not presented by category. | G36: Not applicable/other (please comment).
B37: 26 | C37: Transparency - Executive's Budget Proposal | D37: Does the Executive’s Budget Proposal or any supporting budget documentation present individual sources of revenue for the year preceding the budget year (BY-1)? | E37: Yes, individual sources of revenue accounting for all revenue are presented for BY-1. | F37: Yes, individual sources of revenue accounting for at least two-thirds of, but not all, revenue for BY-1 are presented. | G37: Yes, individual sources of revenue accounting for less than two-thirds of all revenues for BY-1 are presented. | H37: No, individual sources of revenue are not presented for BY-1. | I37: Not applicable/other (please comment).
B38: 27 | C38: Transparency - Executive's Budget Proposal | D38: In the Executive’s Budget Proposal or any supporting budget documentation, have the original estimates of revenue for the year prior to the budget year (BY-1) been updated to reflect actual revenue collections? | E38: Yes, revenue estimates for BY-1 have been updated from the original enacted levels. | F38: No, revenue estimates for BY-1 have not been updated from the original enacted levels. | G38: Not applicable/other (please comment).
B39: 28 | C39: Transparency - Executive's Budget Proposal | D39: Does the Executive’s Budget Proposal or any supporting budget documentation present revenue estimates by category (such as tax and non-tax) for more than one year prior to the budget year (that is, BY-2 and prior years)? | E39: Yes, revenue estimates for BY-2 and prior years are presented by category. | F39: No, revenue estimates for BY-2 and prior years are not presented by category. | G39: Not applicable/other (please comment).
B40: 29 | C40: Transparency - Executive's Budget Proposal | D40: Does the Executive’s Budget Proposal or any supporting budget documentation present individual sources of revenue for more than one year prior to the budget year (that is, BY-2 and prior years)? | E40: Yes, individual sources of revenue accounting for all revenue are presented for BY-2 and prior years. | F40: Yes, individual sources of revenue accounting for at least two-thirds of, but not all, revenue are presented for BY-2 and prior years. | G40: Yes, individual sources of revenue accounting for less than two-thirds of all revenues are presented for BY-2 and prior years. | H40: No, individual sources of revenue are not presented for BY-2 and prior years. | I40: Not applicable/other (please comment).
B41: 30 | C41: Transparency - Executive's Budget Proposal | D41: In the Executive’s Budget Proposal or any supporting budget documentation, what is the most recent year presented for which all revenues reflect actual outcomes? | E41: Two years prior to the budget year (BY-2). | F41: Three years prior to the budget year (BY-3). | G41: Before BY-3. | H41: No actual data for all revenues are presented in the budget or supporting budget documentation. | I41: Not applicable/other (please comment).
B42: 31 | C42: Transparency - Executive's Budget Proposal | D42: Does the Executive’s Budget Proposal or any supporting budget documentation present information on government borrowing and debt, including its composition, for the year preceding the budget year (BY-1)? (The core information must include the total debt outstanding at the end of BY-1; the amount of net new borrowing required during BY-1; interest payments on the debt; interest rates on the debt instruments; maturity profile of the debt; and whether it is domestic or external debt.) | E42: Yes, information beyond the core elements is presented for government debt. | F42: Yes, the core information is presented for government debt. | G42: Yes, information is presented, but it excludes some core elements. | H42: No, information related to government debt is not presented. | I42: Not applicable/other (please comment).
...

Sheet OBS_Data_2006-2025
A1: country | B1: ISO | C1: year | D1: region | E1: comp_region | F1: obi | G1: roundobi | H1: obi_cat | I1: obi_cat2 | J1: obi_cat3 | K1: obi_cat4 | L1: oversight_obi | M1: roundoversight_obi | N1: grade_oversight | O1: leg_obi | P1: roundleg_obi | Q1: grade_leg | R1: sai_obi | S1: roundsai_obi | T1: grade_sai | U1: ifi_obi | V1: roundifi_obi | W1: grade_ifi | X1: pub_eng | Y1: roundpub_eng | Z1: grade_pub_eng | AA1: pbs | AB1: ebp | AC1: eb | AD1: iyr | AE1: myr | AF1: yer | AG1: ar | AH1: cb | AI1: pub_pbs | AJ1: pub_ebp | AK1: pub_eb | AL1: pub_cb | AM1: pub_iyr | AN1: pub_myr | AO1: pub_yer | AP1: pub_ar | AQ1: obi_pbs | AR1: roundobi_pbs | AS1: obi_pbs_cat | AT1: obi_ebp | AU1: roundobi_ebp | AV1: obi_ebp_cat | AW1: obi_eb | AX1: roundobi_eb | AY1: obi_eb_cat | AZ1: obi_cb | BA1: roundobi_cb | BB1: obi_cb_cat | BC1: obi_iyr | BD1: roundobi_iyr | BE1: obi_iyr_cat | BF1: obi_myr | BG1: roundobi_myr | BH1: obi_myr_cat | BI1: obi_yer | BJ1: roundobi_yer | BK1: obi_yer_cat | BL1: obi_ar | BM1: roundobi_ar | BN1: obi_ar_cat | BO1: pbs2 | BP1: ebp2 | BQ1: eb2 | BR1: iyrs2 | BS1: myr2 | BT1: yer2 | BU1: ar2 | BV1: pbs5a | BW1: ebp5a | BX1: eb5a | BY1: iyr5a | BZ1: myr5a | CA1: yer5a | CB1: ar5a | CC1: cb5a | CD1: q1 | CE1: q2 | CF1: q3 | CG1: q4 | CH1: q5 | CI1: q6 | CJ1: q7 | CK1: q8 | CL1: q9 | CM1: q10 | CN1: q11 | CO1: q12 | CP1: q13 | CQ1: q14 | CR1: q15 | CS1: q16 | CT1: q17 | CU1: q18 | CV1: q19 | CW1: q20 | CX1: q21 | CY1: q22 | CZ1: q23 | DA1: q24 | DB1: q25 | DC1: q26 | DD1: q27 | DE1: q28 | DF1: q29 | DG1: q30 | DH1: q31 | DI1: q32 | DJ1: q33 | DK1: q34 | DL1: q35 | DM1: q36 | DN1: q37 | DO1: q38 | DP1: q39 | DQ1: q40 | DR1: q41 | DS1: q42 | DT1: q43 | DU1: q44 | DV1: q45 | DW1: q46 | DX1: q47 | DY1: q48 | DZ1: q49 | EA1: q50 | EB1: q51 | EC1: q52 | ED1: q53 | EE1: q54 | EF1: q55 | EG1: q56 | EH1: q57 | EI1: q58 | EJ1: q59 | EK1: q60 | EL1: q61 | EM1: q62 | EN1: q63 | EO1: q64 | EP1: q65 | EQ1: q66 | ER1: q67 | ES1: q68 | ET1: q69 | EU1: q70 | EV1: q71 | EW1: q72 | EX1: q73 | EY1: q74 | EZ1: q75 | FA1: q76 | FB1: q77 | FC1: q78 | FD1: q79 | FE1: q80 | FF1: q81 | FG1: q82 | FH1: q83 | FI1: q84 | FJ1: q85 | FK1: q86 | FL1: q87 | FM1: q88 | FN1: q89 | FO1: q90 | FP1: q91 | FQ1: q92 | FR1: q93 | FS1: q94 | FT1: q95 | FU1: q96 | FV1: q97 | FW1: q98 | FX1: q99 | FY1: q100 | FZ1: q101 | GA1: q102 | GB1: q103 | GC1: q104 | GD1: q105 | GE1: q106 | GF1: q107 | GG1: q108 | GH1: q109 | GI1: q110 | GJ1: q111 | GK1: q112 | GL1: q113 | GM1: q114 | GN1: q115 | GO1: q116 | GP1: q117 | GQ1: q118 | GR1: q119 | GS1: q120 | GT1: q121 | GU1: q122 | GV1: q123 | GW1: q124 | GX1: q125 | GY1: q126 | GZ1: q127 | HA1: q128 | HB1: q129 | HC1: q130 | HD1: q131 | HE1: q132 | HF1: q133 | HG1: q134 | HH1: q135 | HI1: q136 | HJ1: q137 | HK1: q138 | HL1: q139 | HM1: q140 | HN1: q141 | HO1: q142 | HP1: t3pbs | HQ1: t3ebp | HR1: t3eb | HS1: t3iyr | HT1: t3myr | HU1: t3yer | HV1: t3ar | HW1: new25 | HX1: comp0612 | HY1: comp0812 | HZ1: comp1012 | IA1: comp1215 | IB1: comp1517 | IC1: comp1719 | ID1: comp1921 | IE1: comp2123 | IF1: comp2325
A2: Albania | B2: ALB | C2: 2025 | D2: Eastern Europe & Central Asia | E2: Western Balkans & Turkiye | F2: 64.229358 | G2: 64 | H2: Substantial (61-80) | I2: Sufficient (61-100) | J2: Sufficient (61-100) | K2: 4th Quintile | L2: 68.555556 | M2: 69 | N2: Adequate (61-100) | O2: 63.916667 | P2: 64 | Q2: Adequate (61-100) | R2: 77.833333 | S2: 78 | T2: Adequate (61-100) | U2: 0 | V2: 0 | W2: Weak (0-40) | X2: 16.611111 | Y2: 17 | Z2: Few or no opportunities (0-40) | AA2: PW | AB2: PW | AC2: PW | AD2: PW | AE2: PW | AF2: PW | AG2: PW | AH2: PW | AI2: 1 | AJ2: 1 | AK2: 1 | AL2: 1 | AM2: 1 | AN2: 1 | AO2: 1 | AP2: 1 | AQ2: 94.5 | AR2: 95 | AS2: Extensive (81-100) | AT2: 61.703704 | AU2: 62 | AV2: Substantial (61-80) | AW2: 94.5 | AX2: 95 | AY2: Extensive (81-100) | AZ2: 33.25 | BA2: 33 | BB2: Minimal (21-40) | BC2: 81.555556 | BD2: 82 | BE2: Extensive (81-100) | BF2: 51.888889 | BG2: 52 | BH2: Limited (41-60) | BI2: 54.785714 | BJ2: 55 | BK2: Limited (41-60) | BL2: 62 | BM2: 62 | BN2: Substantial (61-80) | BO2: a | BP2: b | BQ2: b | BR2: b | BS2: a | BT2: a | BU2: b | BV2: e | BW2: e | BX2: e | BY2: e | BZ2: e | CA2: e | CB2: e | CC2: e | CD2: 100 | CE2: 100 | CF2: 100 | CG2: 100 | CH2: 100 | CI2: 100 | CJ2: 67 | CK2: 100 | CL2: 100 | CM2: 67 | CN2: 100 | CO2: 67 | CP2: 100 | CQ2: 33 | CR2: 67 | CS2: 0 | CT2: 0 | CU2: 100 | CV2: 33 | CW2: 0 | CX2: 100 | CY2: 33 | CZ2: 0 | DA2: 100 | DB2: 100 | DC2: 100 | DD2: 100 | DE2: 100 | DF2: 100 | DG2: 100 | DH2: 33 | DI2: 100 | DJ2: 33 | DK2: 100 | DL2: 100 | DM2: 33 | DN2: 33 | DO2: 0 | DP2: 0 | DQ2: 0 | DR2: 0 | DS2: 33 | DT2: 0 | DU2: 67 | DV2: 33 | DW2: 33 | DX2: 67 | DY2: 67 | DZ2: 33 | EA2: 33 | EB2: 67 | EC2: 33 | ED2: 100 | EE2: 100 | EF2: 67 | EG2: 100 | EH2: 100 | EI2: 100 | EJ2: 100 | EK2: 100 | EL2: 100 | EM2: 100 | EN2: 100 | EO2: 67 | EP2: 33 | EQ2: 0 | ER2: 33 | ES2: 100 | ET2: 0 | EU2: 100 | EV2: 100 | EW2: 100 | EX2: 100 | EY2: 100 | EZ2: 67 | FA2: 0 | FB2: 33 | FC2: 33 | FD2: 67 | FE2: 67 | FF2: 100 | FG2: 67 | FH2: 0 | FI2: 100 | FJ2: 100 | FK2: 100 | FL2: 100 | FM2: 100 | FN2: 100 | FO2: 0 | FP2: 0 | FQ2: 0 | FR2: 0 | FS2: 0 | FT2: 67 | FU2: 0 | FV2: 67 | FW2: 33 | FX2: 100 | FY2: 100 | FZ2: 0 | GA2: 67 | GB2: 0 | GC2: 0 | GD2: 0 | GE2: 0 | GF2: 33 | GG2: 67 | GH2: 100 | GI2: 100 | GJ2: 100 | GK2: 67 | GL2: 67 | GM2: 0 | GN2: 0 | GO2: 100 | GP2: 100 | GQ2: 33 | GR2: 100 | GS2: 100 | GT2: 100 | GU2: 100 | GV2: 0 | GW2: 67 | GX2: 33 | GY2: 0 | GZ2: 33 | HA2: 0 | HB2: 0 | HC2: 0 | HD2: 0 | HE2: 0 | HF2: 0 | HG2: 100 | HH2: 33 | HI2: 67 | HJ2: 33 | HK2: 0 | HL2: 0 | HM2: 0 | HN2: 0 | HO2: 0 | HP2: 100 | HQ2: 67 | HR2: 67 | HS2: 67 | HT2: 100 | HU2: 100 | HV2: 67 | HW2: 0 | HX2: 1 | HY2: 1 | HZ2: 1 | IA2: 1 | IB2: 1 | IC2: 1 | ID2: 1 | IE2: 1 | IF2: 1
A3: Albania | B3: ALB | C3: 2023 | D3: Eastern Europe & Central Asia | E3: Western Balkans & Turkiye | F3: 57.477064 | G3: 57 | H3: Limited (41-60) | I3: Limited (41-60) | J3: Insufficient (0-60) | K3: Middle Quintile | L3: 66.666667 | M3: 67 | N3: Adequate (61-100) | O3: 63.916667 | P3: 64 | Q3: Adequate (61-100) | R3: 72.166667 | S3: 72 | T3: Adequate (61-100) | U3: 0 | V3: 0 | W3: Weak (0-40) | X3: 9.1666667 | Y3: 9 | Z3: Few or no opportunities (0-40) | AA3: PW | AB3: PW | AC3: PW | AD3: PW | AE3: PW | AF3: PW | AG3: PW | AH3: IU | AI3: 1 | AJ3: 1 | AK3: 1 | AL3: 0 | AM3: 1 | AN3: 1 | AO3: 1 | AP3: 1 | AQ3: 94.5 | AR3: 95 | AS3: Extensive (81-100) | AT3: 58.592593 | AU3: 59 | AV3: Limited (41-60) | AW3: 94.5 | AX3: 95 | AY3: Extensive (81-100) | AZ3: 0 | BA3: 0 | BB3: Scant or None (0-20) | BC3: 74 | BD3: 74 | BE3: Substantial (61-80 | BF3: 18.555556 | BG3: 19 | BH3: Scant or None (0-20) | BI3: 50 | BJ3: 50 | BK3: Limited (41-60) | BL3: 62 | BM3: 62 | BN3: Substantial (61-80 | BO3: a | BP3: b | BQ3: b | BR3: c | BS3: a | BT3: c | BU3: b | BV3: e | BW3: e | BX3: e | BY3: e | BZ3: e | CA3: e | CB3: e | CD3: 100 | CE3: 100 | CF3: 100 | CG3: 100 | CH3: 100 | CI3: 100 | CJ3: 67 | CK3: 100 | CL3: 100 | CM3: 67 | CN3: 100 | CO3: 67 | CP3: 100 | CQ3: 33 | CR3: 33 | CS3: 0 | CT3: 0 | CU3: 100 | CV3: 33 | CW3: 0 | CX3: 100 | CY3: 33 | CZ3: 0 | DA3: 100 | DB3: 100 | DC3: 100 | DD3: 100 | DE3: 100 | DF3: 100 | DG3: 100 | DH3: 33 | DI3: 100 | DJ3: 33 | DK3: 100 | DL3: 100 | DM3: 33 | DN3: 33 | DO3: 0 | DP3: 0 | DQ3: 0 | DR3: 0 | DS3: 33 | DT3: 0 | DU3: 67 | DV3: 33 | DW3: 0 | DX3: 33 | DY3: 33 | DZ3: 0 | EA3: 33 | EB3: 67 | EC3: 33 | ED3: 100 | EE3: 100 | EF3: 67 | EG3: 100 | EH3: 100 | EI3: 100 | EJ3: 100 | EK3: 100 | EL3: 100 | EM3: 100 | EN3: 100 | EO3: 0 | EP3: 0 | EQ3: 0 | ER3: 0 | ES3: 100 | ET3: 0 | EU3: 100 | EV3: 100 | EW3: 100 | EX3: 100 | EY3: 100 | EZ3: 33 | FA3: 0 | FB3: 0 | FC3: 0 | FD3: 0 | FE3: 67 | FF3: 0 | FG3: 0 | FH3: 0 | FI3: 100 | FJ3: 100 | FK3: 100 | FL3: 100 | FM3: 100 | FN3: 100 | FO3: 0 | FP3: 0 | FQ3: 0 | FR3: 0 | FS3: 0 | FT3: 67 | FU3: 0 | FV3: 67 | FW3: 33 | FX3: 100 | FY3: 100 | FZ3: 0 | GA3: 67 | GB3: 0 | GC3: 0 | GD3: 0 | GE3: 0 | GF3: 33 | GG3: 67 | GH3: 100 | GI3: 100 | GJ3: 100 | GK3: 67 | GL3: 67 | GM3: 0 | GN3: 0 | GO3: 100 | GP3: 100 | GQ3: 33 | GR3: 100 | GS3: 100 | GT3: 100 | GU3: 100 | GV3: 0 | GW3: 33 | GX3: 33 | GY3: 0 | GZ3: 33 | HA3: 0 | HB3: 0 | HC3: 0 | HD3: 0 | HE3: 0 | HF3: 0 | HG3: 0 | HH3: 33 | HI3: 33 | HJ3: 33 | HK3: 0 | HL3: 0 | HM3: 0 | HN3: 0 | HO3: 0 | HP3: 100 | HQ3: 67 | HR3: 67 | HS3: 33 | HT3: 100 | HU3: 33 | HV3: 67 | HW3: 0 | HX3: 1 | HY3: 1 | HZ3: 1 | IA3: 1 | IB3: 1 | IC3: 1 | ID3: 1 | IE3: 1 | IF3: 1
A4: Albania | B4: ALB | C4: 2021 | D4: Eastern Europe & Central Asia | E4: Western Balkans & Turkiye | F4: 51.651376 | G4: 52 | H4: Limited (41-60) | I4: Limited (41-60) | J4: Insufficient (0-60) | K4: Middle Quintile | L4: 66.666667 | M4: 67 | N4: Adequate (61-100) | O4: 63.916667 | P4: 64 | Q4: Adequate (61-100) | R4: 72.166667 | S4: 72 | T4: Adequate (61-100) | U4: 0 | V4: 0 | W4: Weak (0-40) | X4: 5.5 | Y4: 6 | Z4: Few or no opportunities (0-40) | AA4: PW | AB4: PW | AC4: PW | AD4: PW | AE4: PW | AF4: PW | AG4: PL | AH4: PW | AI4: 1 | AJ4: 1 | AK4: 1 | AL4: 1 | AM4: 1 | AN4: 1 | AO4: 1 | AP4: 0 | AQ4: 94.5 | AR4: 95 | AS4: Extensive (81-100) | AT4: 53.037037 | AU4: 53 | AV4: Limited (41-60) | AW4: 94.5 | AX4: 95 | AY4: Extensive (81-100) | AZ4: 33.25 | BA4: 33 | BB4: Minimal (21-40) | BC4: 74 | BD4: 74 | BE4: Substantial (61-80 | BF4: 18.555556 | BG4: 19 | BH4: Scant or None (0-20) | BI4: 42.785714 | BJ4: 43 | BK4: Limited (41-60) | BL4: 9.5714286 | BM4: 10 | BN4: Scant or None (0-20) | BO4: a | BP4: b | BQ4: b | BR4: c | BS4: a | BT4: c | BU4: d | BV4: e | BW4: e | BX4: e | BY4: e | BZ4: e | CA4: e | CB4: a | CD4: 100 | CE4: 100 | CF4: 100 | CG4: 100 | CH4: 100 | CI4: 100 | CJ4: 67 | CK4: 33 | CL4: 100 | CM4: 67 | CN4: 100 | CO4: 67 | CP4: 100 | CQ4: 33 | CR4: 33 | CS4: 0 | CT4: 0 | CU4: 0 | CV4: 33 | CW4: 0 | CX4: 100 | CY4: 33 | CZ4: 0 | DA4: 100 | DB4: 100 | DC4: 100 | DD4: 100 | DE4: 100 | DF4: 100 | DG4: 100 | DH4: 33 | DI4: 0 | DJ4: 33 | DK4: 100 | DL4: 100 | DM4: 0 | DN4: 33 | DO4: 0 | DP4: 0 | DQ4: 0 | DR4: 0 | DS4: 33 | DT4: 0 | DU4: 67 | DV4: 33 | DW4: 0 | DX4: 33 | DY4: 33 | DZ4: 0 | EA4: 33 | EB4: 67 | EC4: 33 | ED4: 100 | EE4: 100 | EF4: 67 | EG4: 100 | EH4: 100 | EI4: 100 | EJ4: 100 | EK4: 100 | EL4: 100 | EM4: 100 | EN4: 100 | EO4: 67 | EP4: 33 | EQ4: 0 | ER4: 33 | ES4: 100 | ET4: 0 | EU4: 100 | EV4: 100 | EW4: 100 | EX4: 100 | EY4: 100 | EZ4: 33 | FA4: 0 | FB4: 0 | FC4: 0 | FD4: 0 | FE4: 67 | FF4: 0 | FG4: 0 | FH4: 0 | FI4: 100 | FJ4: 100 | FK4: 33 | FL4: 100 | FM4: 100 | FN4: 100 | FO4: 0 | FP4: 0 | FQ4: 0 | FR4: 0 | FS4: 0 | FT4: 33 | FU4: 0 | FV4: 0 | FW4: 0 | FX4: 0 | FY4: 0 | FZ4: 0 | GA4: 67 | GB4: 0 | GC4: 0 | GD4: 0 | GE4: 0 | GF4: 33 | GG4: 67 | GH4: 100 | GI4: 100 | GJ4: 100 | GK4: 67 | GL4: 67 | GM4: 0 | GN4: 0 | GO4: 100 | GP4: 100 | GQ4: 33 | GR4: 100 | GS4: 100 | GT4: 100 | GU4: 100 | GV4: 0 | GW4: 33 | GX4: 0 | GY4: 0 | GZ4: 0 | HA4: 0 | HB4: 0 | HC4: 0 | HD4: 0 | HE4: 0 | HF4: 0 | HG4: 0 | HH4: 33 | HI4: 33 | HJ4: 33 | HK4: 0 | HL4: 0 | HM4: 0 | HN4: 0 | HO4: 0 | HP4: 100 | HQ4: 67 | HR4: 67 | HS4: 33 | HT4: 100 | HU4: 33 | HV4: 0 | HW4: 0 | HX4: 1 | HY4: 1 | HZ4: 1 | IA4: 1 | IB4: 1 | IC4: 1 | ID4: 1 | IE4: 1 | IF4: 1
A5: Albania | B5: ALB | C5: 2019 | D5: Eastern Europe & Central Asia | E5: Western Balkans & Turkiye | F5: 54.715596 | G5: 55 | H5: Limited (41-60) | I5: Limited (41-60) | J5: Insufficient (0-60) | K5: Middle Quintile | L5: 64.777778 | M5: 65 | N5: Adequate (61-100) | O5: 61.083333 | P5: 61 | Q5: Adequate (61-100) | R5: 72.166667 | S5: 72 | T5: Adequate (61-100) | U5: 0 | V5: 0 | W5: Weak (0-40) | X5: 7.3333333 | Y5: 7 | Z5: Few or no opportunities (0-40) | AA5: PW | AB5: PW | AC5: PW | AD5: PW | AE5: PW | AF5: PW | AG5: PW | AH5: PW | AI5: 1 | AJ5: 1 | AK5: 1 | AL5: 1 | AM5: 1 | AN5: 1 | AO5: 1 | AP5: 1 | AQ5: 94.5 | AR5: 95 | AS5: Extensive (81-100) | AT5: 49.351852 | AU5: 49 | AV5: Limited (41-60) | AW5: 100 | AX5: 100 | AY5: Extensive (81-100) | AZ5: 33.25 | BA5: 33 | BB5: Minimal (21-40) | BC5: 81.444444 | BD5: 81 | BE5: Extensive (81-100) | BF5: 18.444444 | BG5: 18 | BH5: Scant or None (0-20) | BI5: 42.857143 | BJ5: 43 | BK5: Limited (41-60) | BL5: 71.428571 | BM5: 71 | BN5: Substantial (61-80 | BO5: a | BP5: b | BQ5: a | BR5: a | BS5: a | BT5: b | BU5: b | BV5: e | BW5: e | BX5: e | BY5: e | BZ5: e | CA5: e | CB5: e | CD5: 100 | CE5: 100 | CF5: 100 | CG5: 100 | CH5: 0 | CI5: 100 | CJ5: 67 | CK5: 67 | CL5: 100 | CM5: 67 | CN5: 100 | CO5: 67 | CP5: 100 | CQ5: 33 | CR5: 33 | CS5: 0 | CT5: 67 | CU5: 0 | CV5: 33 | CW5: 0 | CX5: 100 | CY5: 33 | CZ5: 0 | DA5: 100 | DB5: 100 | DC5: 100 | DD5: 100 | DE5: 100 | DF5: 100 | DG5: 100 | DH5: 33 | DI5: 0 | DJ5: 33 | DK5: 100 | DL5: 100 | DM5: 0 | DN5: 33 | DO5: 0 | DP5: 0 | DQ5: 0 | DR5: 0 | DS5: 33 | DT5: 0 | DU5: 0 | DV5: 33 | DW5: 0 | DX5: 33 | DY5: 33 | DZ5: 0 | EA5: 0 | EB5: 0 | EC5: 0 | ED5: 100 | EE5: 100 | EF5: 67 | EG5: 100 | EH5: 100 | EI5: 100 | EJ5: 100 | EK5: 100 | EL5: 100 | EM5: 100 | EN5: 100 | EO5: 67 | EP5: 33 | EQ5: 0 | ER5: 33 | ES5: 100 | ET5: 0 | EU5: 100 | EV5: 100 | EW5: 100 | EX5: 100 | EY5: 100 | EZ5: 33 | FA5: 33 | FB5: 0 | FC5: 0 | FD5: 0 | FE5: 33 | FF5: 0 | FG5: 0 | FH5: 0 | FI5: 100 | FJ5: 67 | FK5: 33 | FL5: 100 | FM5: 100 | FN5: 100 | FO5: 0 | FP5: 0 | FQ5: 0 | FR5: 0 | FS5: 0 | FT5: 33 | FU5: 0 | FV5: 100 | FW5: 100 | FX5: 100 | FY5: 100 | FZ5: 0 | GA5: 33 | GB5: 0 | GC5: 0 | GD5: 0 | GE5: 0 | GF5: 33 | GG5: 33 | GH5: 67 | GI5: 100 | GJ5: 100 | GK5: 67 | GL5: 33 | GM5: 0 | GN5: 0 | GO5: 100 | GP5: 100 | GQ5: 100 | GR5: 100 | GS5: 100 | GT5: 100 | GU5: 100 | GV5: 0 | GW5: 33 | GX5: 0 | GY5: 0 | GZ5: 0 | HA5: 0 | HB5: 0 | HC5: 0 | HD5: 0 | HE5: 0 | HF5: 0 | HG5: 0 | HH5: 33 | HI5: 33 | HJ5: 33 | HK5: 33 | HL5: 0 | HM5: 0 | HN5: 0 | HO5: 0 | HP5: 100 | HQ5: 67 | HR5: 100 | HS5: 100 | HT5: 100 | HU5: 67 | HV5: 67 | HW5: 0 | HX5: 1 | HY5: 1 | HZ5: 1 | IA5: 1 | IB5: 1 | IC5: 1 | ID5: 1 | IE5: 1 | IF5: 1
A6: Albania | B6: ALB | C6: 2017 | D6: Eastern Europe & Central Asia | E6: Western Balkans & Turkiye | F6: 49.657407 | G6: 50 | H6: Limited (41-60) | I6: Limited (41-60) | J6: Insufficient (0-60) | K6: Middle Quintile | L6: 68.5 | M6: 69 | N6: Adequate (61-100) | O6: 66.666667 | P6: 67 | Q6: Adequate (61-100) | R6: 72.166667 | S6: 72 | T6: Adequate (61-100) | U6: 0 | V6: 0 | W6: Weak (0-40) | X6: 1.8333333 | Y6: 2 | Z6: Few or No (0-40) | AA6: PW | AB6: PW | AC6: PW | AD6: PW | AE6: NP | AF6: PW | AG6: PW | AH6: PW | AI6: 1 | AJ6: 1 | AK6: 1 | AL6: 1 | AM6: 1 | AN6: 0 | AO6: 1 | AP6: 1 | AQ6: 94.5 | AR6: 95 | AS6: Extensive (81-100) | AT6: 49 | AU6: 49 | AV6: Limited (41-60) | AW6: 89 | AX6: 89 | AY6: Extensive (81-100) | AZ6: 33.25 | BA6: 33 | BB6: Minimal (21-40) | BC6: 74 | BD6: 74 | BE6: Substantial (61-80 | BF6: 0 | BG6: 0 | BH6: Scant or None (0-20) | BI6: 26.142857 | BJ6: 26 | BK6: Minimal (21-40) | BL6: 71.428571 | BM6: 71 | BN6: Substantial (61-80 | BO6: a | BP6: c | BQ6: b | BR6: c | BS6: d | BT6: c | BU6: b | CD6: 100 | CE6: 100 | CF6: 100 | CG6: 100 | CH6: 0 | CI6: 100 | CJ6: 33 | CK6: 0 | CL6: 100 | CM6: 67 | CN6: 100 | CO6: 67 | CP6: 100 | CQ6: 33 | CR6: 33 | CS6: 0 | CT6: 0 | CU6: 0 | CV6: 33 | CW6: 0 | CX6: 100 | CY6: 33 | CZ6: 0 | DA6: 100 | DB6: 100 | DC6: 100 | DD6: 100 | DE6: 100 | DF6: 100 | DG6: 100 | DH6: 33 | DI6: 100 | DJ6: 33 | DK6: 100 | DL6: 100 | DM6: 0 | DN6: 33 | DO6: 67 | DP6: 0 | DQ6: 0 | DS6: 33 | DT6: 0 | DU6: 0 | DV6: 33 | DW6: 0 | DX6: 33 | DY6: 0 | DZ6: 0 | EA6: 0 | EB6: 0 | EC6: 0 | ED6: 100 | EE6: 100 | EF6: 67 | EG6: 100 | EH6: 100 | EI6: 100 | EJ6: 100 | EK6: 100 | EL6: 100 | EM6: 100 | EN6: 67 | EO6: 67 | EP6: 33 | EQ6: 0 | ER6: 33 | ES6: 100 | ET6: 0 | EU6: 100 | EV6: 100 | EW6: 100 | EX6: 100 | EY6: 100 | EZ6: 33 | FA6: 0 | FB6: 0 | FC6: 0 | FD6: 0 | FE6: 0 | FF6: 0 | FG6: 0 | FH6: 0 | FI6: 33 | FJ6: 0 | FK6: 0 | FL6: 100 | FM6: 100 | FN6: 100 | FO6: 0 | FP6: 0 | FQ6: 0 | FR6: 0 | FS6: 0 | FT6: 0 | FU6: 0 | FV6: 100 | FW6: 100 | FX6: 100 | FY6: 100 | FZ6: 0 | GA6: 33 | GB6: 0 | GC6: 0 | GD6: 0 | GE6: 0 | GF6: 33 | GG6: 67 | GH6: 67 | GI6: 100 | GJ6: 100 | GK6: 67 | GL6: 33 | GM6: 33 | GN6: 0 | GO6: 100 | GP6: 100 | GQ6: 100 | GR6: 100 | GS6: 100 | GT6: 100 | GU6: 100 | GV6: 0 | GW6: 33 | GX6: 0 | GY6: 0 | GZ6: 0 | HA6: 0 | HB6: 0 | HC6: 0 | HD6: 0 | HE6: 0 | HF6: 0 | HG6: 0 | HH6: 0 | HI6: 33 | HJ6: 0 | HK6: 0 | HL6: 0 | HM6: 0 | HN6: 0 | HO6: 0 | HP6: 100 | HQ6: 33 | HR6: 67 | HS6: 33 | HT6: 0 | HU6: 33 | HV6: 67 | HW6: 0 | HX6: 1 | HY6: 1 | HZ6: 1 | IA6: 1 | IB6: 1 | IC6: 1 | ID6: 1 | IE6: 1 | IF6: 1
A7: Albania | B7: ALB | C7: 2015 | D7: Eastern Europe & Central Asia | E7: Western Balkans & Turkiye | F7: 38.2202 | G7: 38 | H7: Minimal (21-40) | I7: Low (0-40) | J7: Insufficient (0-60) | K7: 2nd Quintile | O7: 48.545502 | P7: 49 | Q7: Moderate | R7: 91.75 | S7: 92 | T7: Strong | X7: 14.5625 | Y7: 15 | Z7: Minimal | AA7: PW | AB7: PW | AC7: PW | AD7: PW | AE7: NP | AF7: IU | AG7: PW | AH7: NP | AI7: 1 | AJ7: 1 | AK7: 1 | AL7: 0 | AM7: 1 | AN7: 0 | AO7: 0 | AP7: 1 | AQ7: 72.166702 | AR7: 72 | AS7: Substantial (61-80 | AT7: 40.092602 | AU7: 40 | AV7: Minimal (21-40) | AW7: 94.5 | AX7: 95 | AY7: Extensive (81-100) | AZ7: 0 | BA7: 0 | BB7: Scant or None (0-20) | BC7: 77.777802 | BD7: 78 | BE7: Substantial (61-80 | BF7: 0 | BG7: 0 | BH7: Scant or None (0-20) | BI7: 0 | BJ7: 0 | BK7: Scant or None (0-20) | BL7: 43 | BM7: 43 | BN7: Limited (41-60) | CD7: 100 | CE7: 100 | CF7: 100 | CG7: 100 | CH7: 0 | CI7: 100 | CJ7: 0 | CK7: 0 | CL7: 100 | CM7: 100 | CN7: 0 | CO7: 0 | CP7: 100 | CQ7: 100 | CR7: 33 | CS7: 0 | CT7: 0 | CU7: 0 | CV7: 0 | CW7: 0 | CX7: 100 | CY7: 0 | CZ7: 0 | DA7: 100 | DB7: 100 | DC7: 67 | DD7: 100 | DE7: 0 | DF7: 0 | DG7: 0 | DH7: 100 | DI7: 100 | DJ7: 33 | DK7: 100 | DL7: 100 | DM7: 0 | DN7: 33 | DO7: 0 | DP7: 0 | DQ7: 0 | DR7: 100 | DS7: 33 | DT7: 0 | DU7: 0 | DV7: 33 | DW7: 0 | DX7: 0 | DY7: 0 | DZ7: 0 | EA7: 0 | EB7: 0 | EC7: 0 | ED7: 100 | EE7: 67 | EF7: 33 | EG7: 33 | EH7: 100 | EI7: 100 | EJ7: 100 | EK7: 100 | EL7: 100 | EM7: 100 | EN7: 67 | EO7: 0 | EP7: 0 | EQ7: 0 | ER7: 0 | ES7: 100 | ET7: 0 | EU7: 100 | EV7: 100 | EW7: 100 | EX7: 100 | EY7: 67 | EZ7: 33 | FA7: 0 | FB7: 0 | FC7: 0 | FD7: 0 | FE7: 0 | FF7: 0 | FG7: 0 | FH7: 0 | FI7: 0 | FJ7: 0 | FK7: 0 | FL7: 0 | FM7: 0 | FN7: 0 | FO7: 0 | FP7: 0 | FQ7: 0 | FR7: 0 | FS7: 0 | FT7: 0 | FU7: 0 | FV7: 67 | FW7: 67 | FX7: 100 | FY7: 0 | FZ7: 0 | GA7: 0 | GB7: 0 | GC7: 67 | GD7: 67 | GE7: 33 | GF7: 67 | GG7: 100 | GH7: 0 | GI7: 0 | GJ7: 100 | GK7: 100 | GL7: 0 | GM7: 100 | GN7: 100 | GO7: 67 | GP7: 100 | GQ7: 100 | GR7: 0 | GS7: 0 | GT7: 0 | GU7: 0 | GV7: 0 | GW7: 0 | GX7: 0 | GY7: 33 | GZ7: 67 | HA7: 33 | HB7: 0 | HC7: 0 | HD7: 0 | HE7: 0 | HF7: 0 | HP7: 100 | HQ7: 33 | HR7: 100 | HS7: 100 | HT7: 0 | HU7: 0 | HV7: 67 | HW7: 0 | HX7: 1 | HY7: 1 | HZ7: 1 | IA7: 1 | IB7: 1 | IC7: 1 | ID7: 1 | IE7: 1 | IF7: 1
A8: Albania | B8: ALB | C8: 2012 | D8: Eastern Europe & Central Asia | E8: Western Balkans & Turkiye | F8: 46.694698 | G8: 47 | H8: Limited (41-60) | I8: Limited (41-60) | J8: Insufficient (0-60) | K8: Middle Quintile | O8: 51.545502 | P8: 52 | Q8: Moderate | R8: 100 | S8: 100 | T8: Strong | X8: 11.0833 | Y8: 11 | Z8: Weak | AA8: PW | AB8: PW | AC8: PW | AD8: PW | AE8: NP | AF8: IU | AG8: PW | AH8: NP | AI8: 1 | AJ8: 1 | AK8: 1 | AL8: 0 | AM8: 1 | AN8: 0 | AO8: 0 | AP8: 1 | AQ8: 100 | AR8: 100 | AS8: Extensive (81-100) | AT8: 50.0172 | AU8: 50 | AV8: Limited (41-60) | AW8: 100 | AX8: 100 | AY8: Extensive (81-100) | AZ8: 0 | BA8: 0 | BB8: Scant or None (0-20) | BC8: 95.875 | BD8: 96 | BE8: Extensive (81-100) | BF8: 0 | BG8: 0 | BH8: Scant or None (0-20) | BI8: 0 | BJ8: 0 | BK8: Scant or None (0-20) | BL8: 52.5714 | BM8: 53 | BN8: Limited (41-60) | CD8: 100 | CI8: 100 | CL8: 100 | CM8: 67 | CQ8: 100 | CR8: 100 | CS8: 0 | CT8: 0 | CU8: 0 | CW8: 0 | CX8: 100 | DA8: 100 | DD8: 100 | DG8: 100 | DH8: 33 | DI8: 100 | DJ8: 67 | DL8: 100 | DN8: 67 | DO8: 0 | DP8: 0 | DQ8: 0 | DR8: 0 | DS8: 33 | DT8: 0 | DU8: 0 | DV8: 0 | DW8: 0 | DX8: 0 | DY8: 0 | EA8: 0 | EB8: 0 | EC8: 0 | ED8: 100 | EE8: 100 | EO8: 0 | EP8: 0 | EQ8: 0 | ER8: 0 | EU8: 100 | EW8: 100 | EX8: 100 | EZ8: 67 | FA8: 0 | FB8: 0 | FE8: 0 | FI8: 0 | FL8: 0 | FP8: 0 | FQ8: 0 | FR8: 0 | FS8: 0 | FT8: 0 | FW8: 67 | FX8: 67 | FY8: 0 | FZ8: 0 | GA8: 67 | GB8: 0 | GC8: 67 | GD8: 67 | GE8: 67 | GG8: 100 | GH8: 33 | GI8: 33 | GJ8: 100 | GK8: 0 | GL8: 0 | GM8: 100 | GN8: 100 | GP8: 100 | GQ8: 100 | GR8: 0 | GS8: 0 | GT8: 0 | GV8: 0 | GW8: 0 | GX8: 0 | GY8: 33 | GZ8: 67 | HA8: 33 | HB8: 0 | HE8: 0 | HF8: 0 | HP8: 100 | HQ8: 67 | HS8: 100 | HU8: 0 | HV8: 67 | HW8: 0 | HX8: 1 | HY8: 1 | HZ8: 1 | IA8: 1 | IB8: 1 | IC8: 1 | ID8: 1 | IE8: 1 | IF8: 1
A9: Albania | B9: ALB | C9: 2010 | D9: Eastern Europe & Central Asia | E9: Western Balkans & Turkiye | F9: 32.9674 | G9: 33 | H9: Minimal (21-40) | I9: Low (0-40) | J9: Insufficient (0-60) | K9: 2nd Quintile | O9: 44.5 | P9: 45 | Q9: Moderate | R9: 50 | S9: 50 | T9: Moderate | AA9: IU | AB9: PW | AC9: PW | AD9: PW | AE9: IU | AF9: PW | AG9: HC | AH9: NP | AI9: 0 | AJ9: 1 | AK9: 1 | AL9: 0 | AM9: 1 | AN9: 0 | AO9: 1 | AP9: 1 | AQ9: 0 | AR9: 0 | AS9: Scant or None (0-20) | AT9: 30.8909 | AU9: 31 | AV9: Minimal (21-40) | AW9: 67 | AX9: 67 | AY9: Substantial (61-80 | AZ9: 0 | BA9: 0 | BB9: Scant or None (0-20) | BC9: 79.25 | BD9: 79 | BE9: Substantial (61-80 | BF9: 0 | BG9: 0 | BH9: Scant or None (0-20) | BI9: 16.6 | BJ9: 17 | BK9: Scant or None (0-20) | BL9: 23.8571 | BM9: 24 | BN9: Minimal (21-40) | CD9: 67 | CI9: 67 | CL9: 67 | CM9: 33 | CQ9: 33 | CR9: 33 | CS9: 0 | CT9: 33 | CU9: 33 | CW9: 0 | CX9: 0 | DA9: 0 | DD9: 0 | DG9: 0 | DH9: 33 | DI9: 0 | DJ9: 100 | DL9: 67 | DN9: 0 | DO9: 0 | DP9: 0 | DQ9: 0 | DR9: 0 | DS9: 0 | DT9: 0 | DU9: 0 | DV9: 0 | DW9: 0 | DX9: 33 | DY9: 67 | EA9: 67 | EB9: 0 | EC9: 0 | ED9: 100 | EE9: 0 | EO9: 0 | EU9: 100 | EW9: 100 | EX9: 100 | EZ9: 33 | FA9: 0 | FB9: 0 | FE9: 0 | FI9: 33 | FL9: 0 | FP9: 0 | FQ9: 33 | FR9: 0 | FS9: 0 | FT9: 0 | FW9: 67 | FX9: 0 | FY9: 0 | FZ9: 0 | GA9: 0 | GD9: 67 | GE9: 67 | GG9: 67 | GH9: 33 | GK9: 100 | GL9: 0 | GM9: 67 | GN9: 100 | GP9: 100 | GQ9: 100 | GR9: 100 | GY9: 33 | GZ9: 67 | HA9: 33 | HB9: 0 | HP9: 0 | HQ9: 67 | HS9: 67 | HU9: 67 | HV9: 67 | HW9: 0 | HX9: 1 | HY9: 1 | HZ9: 1 | IA9: 1 | IB9: 1 | IC9: 1 | ID9: 1 | IE9: 1 | IF9: 1
A10: Albania | B10: ALB | C10: 2008 | D10: Eastern Europe & Central Asia | E10: Western Balkans & Turkiye | F10: 37.3297 | G10: 37 | H10: Minimal (21-40) | I10: Low (0-40) | J10: Insufficient (0-60) | K10: 2nd Quintile | O10: 41.583302 | P10: 42 | Q10: Moderate | R10: 66.800003 | S10: 67 | T10: Strong | AA10: IU | AB10: PW | AC10: PW | AD10: PW | AE10: IU | AF10: IU | AG10: PW | AH10: NP | AI10: 0 | AJ10: 1 | AK10: 1 | AL10: 0 | AM10: 1 | AN10: 0 | AO10: 0 | AP10: 1 | AQ10: 0 | AR10: 0 | AS10: Scant or None (0-20) | AT10: 40.055599 | AU10: 40 | AV10: Minimal (21-40) | AW10: 33 | AX10: 33 | AY10: Minimal (21-40) | AZ10: 0 | BA10: 0 | BB10: Scant or None (0-20) | BC10: 91.625 | BD10: 92 | BE10: Extensive (81-100) | BF10: 0 | BG10: 0 | BH10: Scant or None (0-20) | BI10: 0 | BJ10: 0 | BK10: Scant or None (0-20) | BL10: 28.7143 | BM10: 29 | BN10: Minimal (21-40) | CD10: 33 | CI10: 0 | CL10: 67 | CM10: 33 | CQ10: 33 | CR10: 33 | CS10: 0 | CT10: 0 | CU10: 33 | CW10: 0 | CX10: 33 | DA10: 100 | DD10: 67 | DG10: 0 | DH10: 33 | DI10: 100 | DJ10: 100 | DL10: 67 | DN10: 33 | DO10: 0 | DP10: 0 | DQ10: 0 | DR10: 33 | DS10: 33 | DT10: 33 | DU10: 0 | DV10: 0 | DX10: 33 | DY10: 33 | EA10: 33 | EB10: 0 | EC10: 0 | ED10: 100 | EE10: 0 | EO10: 0 | EU10: 100 | EW10: 100 | EX10: 100 | EZ10: 33 | FA10: 0 | FB10: 0 | FE10: 0 | FI10: 0 | FL10: 0 | FP10: 0 | FQ10: 0 | FR10: 0 | FS10: 0 | FT10: 0 | FW10: 67 | FX10: 0 | FY10: 0 | FZ10: 0 | GA10: 0 | GD10: 0 | GE10: 33 | GG10: 100 | GH10: 0 | GK10: 100 | GL10: 0 | GM10: 67 | GN10: 100 | GP10: 100 | GQ10: 100 | GR10: 0 | GY10: 33 | GZ10: 67 | HA10: 33 | HB10: 0 | HP10: 0 | HQ10: 33 | HS10: 100 | HU10: 0 | HV10: 67 | HW10: 0 | HX10: 1 | HY10: 1 | HZ10: 1 | IA10: 1 | IB10: 1 | IC10: 1 | ID10: 1 | IE10: 1 | IF10: 1
